test_four (test_soldier.TestEligibility) ... ok
test_one (test_soldier.TestEligibility) ... ok
test_three (test_soldier.TestEligibility) ... FAIL
test_two (test_soldier.TestEligibility) ... ok
test_five (test1.TestEligibility1) ... ok
test_four (test1.TestEligibility1) ... ok
test_one (test1.TestEligibility1) ... ok
test_seven (test1.TestEligibility1) ... FAIL
test_six (test1.TestEligibility1) ... ok
test_three (test1.TestEligibility1) ... FAIL
test_two (test1.TestEligibility1) ... ok
test_five_abc (test2.TestEligibility2) ... ok
test_four_abc (test2.TestEligibility2) ... ok
test_one_abc (test2.TestEligibility2) ... ok
test_seven_abc (test2.TestEligibility2) ... FAIL
test_six_abc (test2.TestEligibility2) ... ok
test_three_abc (test2.TestEligibility2) ... FAIL
test_two_abc (test2.TestEligibility2) ... ok
test_five_abc (test3.TestEligibility4) ... ok
test_four_abc (test3.TestEligibility4) ... ok
test_one_abc (test3.TestEligibility4) ... ok
test_seven_abc (test3.TestEligibility4) ... FAIL
test_six_abc (test3.TestEligibility4) ... FAIL
test_three_abc (test3.TestEligibility4) ... FAIL
test_two_abc (test3.TestEligibility4) ... ok
test_five_abc (test4.TestEligibility3) ... ok
test_four_abc (test4.TestEligibility3) ... ok
test_one_abc (test4.TestEligibility3) ... ok
test_seven_abc (test4.TestEligibility3) ... FAIL
test_six_abc (test4.TestEligibility3) ... ok
test_three_abc (test4.TestEligibility3) ... FAIL
test_two_abc (test4.TestEligibility3) ... ok

======================================================================
FAIL: test_three (test_soldier.TestEligibility)
----------------------------------------------------------------------
Traceback (most recent call last):
  File "D:\bk_python\pyunit\army\test_soldier.py", line 15, in test_three
    self.assertEqual(self.candidate3.checkagelimit(),True)
AssertionError: False != True

======================================================================
FAIL: test_seven (test1.TestEligibility1)
----------------------------------------------------------------------
Traceback (most recent call last):
  File "D:\bk_python\pyunit\army\test1.py", line 26, in test_seven
    self.assertEqual(self.candidate7.checkagelimit(),False)
AssertionError: True != False

======================================================================
FAIL: test_three (test1.TestEligibility1)
----------------------------------------------------------------------
Traceback (most recent call last):
  File "D:\bk_python\pyunit\army\test1.py", line 18, in test_three
    self.assertEqual(self.candidate3.checkagelimit(),True)
AssertionError: False != True

======================================================================
FAIL: test_seven_abc (test2.TestEligibility2)
----------------------------------------------------------------------
Traceback (most recent call last):
  File "D:\bk_python\pyunit\army\test2.py", line 26, in test_seven_abc
    self.assertEqual(self.candidate17.checkagelimit(),False)
AssertionError: True != False

======================================================================
FAIL: test_three_abc (test2.TestEligibility2)
----------------------------------------------------------------------
Traceback (most recent call last):
  File "D:\bk_python\pyunit\army\test2.py", line 18, in test_three_abc
    self.assertEqual(self.candidate13.checkagelimit(),True)
AssertionError: False != True

======================================================================
FAIL: test_seven_abc (test3.TestEligibility4)
----------------------------------------------------------------------
Traceback (most recent call last):
  File "D:\bk_python\pyunit\army\test3.py", line 26, in test_seven_abc
    self.assertEqual(self.candidate17.checkagelimit(),False)
AssertionError: True != False

======================================================================
FAIL: test_six_abc (test3.TestEligibility4)
----------------------------------------------------------------------
Traceback (most recent call last):
  File "D:\bk_python\pyunit\army\test3.py", line 24, in test_six_abc
    self.assertEqual(self.candidate16.checkagelimit(),True)
AssertionError: False != True

======================================================================
FAIL: test_three_abc (test3.TestEligibility4)
----------------------------------------------------------------------
Traceback (most recent call last):
  File "D:\bk_python\pyunit\army\test3.py", line 18, in test_three_abc
    self.assertEqual(self.candidate13.checkagelimit(),True)
AssertionError: False != True

======================================================================
FAIL: test_seven_abc (test4.TestEligibility3)
----------------------------------------------------------------------
Traceback (most recent call last):
  File "D:\bk_python\pyunit\army\test4.py", line 26, in test_seven_abc
    self.assertEqual(self.candidate17.checkagelimit(),False)
AssertionError: True != False

======================================================================
FAIL: test_three_abc (test4.TestEligibility3)
----------------------------------------------------------------------
Traceback (most recent call last):
  File "D:\bk_python\pyunit\army\test4.py", line 18, in test_three_abc
    self.assertEqual(self.candidate13.checkagelimit(),True)
AssertionError: False != True

----------------------------------------------------------------------
Ran 32 tests in 0.006s

FAILED (failures=10)

----------------------------------------------------------------------
Ran 0 tests in 0.000s

OK
